2024-06-30 10:03:28,074 INFO    StreamThr :15384 [internal.py:wandb_internal():85] W&B internal server running at pid: 15384, started at: 2024-06-30 10:03:28.073569
2024-06-30 10:03:28,075 DEBUG   HandlerThread:15384 [handler.py:handle_request():158] handle_request: status
2024-06-30 10:03:28,079 INFO    WriterThread:15384 [datastore.py:open_for_write():87] open: E:\huggingface_ex\wandb\run-20240630_100328-ylejexp4\run-ylejexp4.wandb
2024-06-30 10:03:28,080 DEBUG   SenderThread:15384 [sender.py:send():379] send: header
2024-06-30 10:03:28,115 DEBUG   SenderThread:15384 [sender.py:send():379] send: run
2024-06-30 10:03:28,712 ERROR   SenderThread:15384 [internal_api.py:execute():344] 404 response executing GraphQL.
2024-06-30 10:03:28,712 ERROR   SenderThread:15384 [internal_api.py:execute():345] {"errors":[{"message":"project not found","path":["upsertBucket"]}],"data":{"upsertBucket":null}}
2024-06-30 10:03:28,715 ERROR   SenderThread:15384 [sender.py:send_run():1009] It appears that you do not have permission to access the requested resource. Please reach out to the project owner to grant you access. If you have the correct permissions, verify that there are no issues with your networking setup.(Error 404: Not Found)
Traceback (most recent call last):
  File "C:\Users\Wen-Liang\AppData\Local\Programs\Python\Python311\Lib\site-packages\wandb\sdk\lib\retry.py", line 131, in __call__
    result = self._call_fn(*args, **kwargs)
             ^^^^^^^^^^^^^^^^^^^^^^^^^^^^^^
  File "C:\Users\Wen-Liang\AppData\Local\Programs\Python\Python311\Lib\site-packages\wandb\sdk\internal\internal_api.py", line 340, in execute
    return self.client.execute(*args, **kwargs)  # type: ignore
           ^^^^^^^^^^^^^^^^^^^^^^^^^^^^^^^^^^^^
  File "C:\Users\Wen-Liang\AppData\Local\Programs\Python\Python311\Lib\site-packages\wandb\vendor\gql-0.2.0\wandb_gql\client.py", line 52, in execute
    result = self._get_result(document, *args, **kwargs)
             ^^^^^^^^^^^^^^^^^^^^^^^^^^^^^^^^^^^^^^^^^^^
  File "C:\Users\Wen-Liang\AppData\Local\Programs\Python\Python311\Lib\site-packages\wandb\vendor\gql-0.2.0\wandb_gql\client.py", line 60, in _get_result
    return self.transport.execute(document, *args, **kwargs)
           ^^^^^^^^^^^^^^^^^^^^^^^^^^^^^^^^^^^^^^^^^^^^^^^^^
  File "C:\Users\Wen-Liang\AppData\Local\Programs\Python\Python311\Lib\site-packages\wandb\sdk\lib\gql_request.py", line 59, in execute
    request.raise_for_status()
  File "C:\Users\Wen-Liang\AppData\Local\Programs\Python\Python311\Lib\site-packages\requests\models.py", line 1021, in raise_for_status
    raise HTTPError(http_error_msg, response=self)
requests.exceptions.HTTPError: 404 Client Error: Not Found for url: https://api.wandb.ai/graphql

During handling of the above exception, another exception occurred:

Traceback (most recent call last):
  File "C:\Users\Wen-Liang\AppData\Local\Programs\Python\Python311\Lib\site-packages\wandb\sdk\internal\sender.py", line 1007, in send_run
    server_run = self._init_run(run, config_value_dict)
                 ^^^^^^^^^^^^^^^^^^^^^^^^^^^^^^^^^^^^^^
  File "C:\Users\Wen-Liang\AppData\Local\Programs\Python\Python311\Lib\site-packages\wandb\sdk\internal\sender.py", line 1079, in _init_run
    server_run, inserted, server_messages = self._api.upsert_run(
                                            ^^^^^^^^^^^^^^^^^^^^^
  File "C:\Users\Wen-Liang\AppData\Local\Programs\Python\Python311\Lib\site-packages\wandb\apis\normalize.py", line 73, in wrapper
    raise err
  File "C:\Users\Wen-Liang\AppData\Local\Programs\Python\Python311\Lib\site-packages\wandb\apis\normalize.py", line 41, in wrapper
    return func(*args, **kwargs)
           ^^^^^^^^^^^^^^^^^^^^^
  File "C:\Users\Wen-Liang\AppData\Local\Programs\Python\Python311\Lib\site-packages\wandb\sdk\internal\internal_api.py", line 2190, in upsert_run
    response = self.gql(
               ^^^^^^^^^
  File "C:\Users\Wen-Liang\AppData\Local\Programs\Python\Python311\Lib\site-packages\wandb\sdk\internal\internal_api.py", line 312, in gql
    ret = self._retry_gql(
          ^^^^^^^^^^^^^^^^
  File "C:\Users\Wen-Liang\AppData\Local\Programs\Python\Python311\Lib\site-packages\wandb\sdk\lib\retry.py", line 147, in __call__
    retry_timedelta_triggered = check_retry_fn(e)
                                ^^^^^^^^^^^^^^^^^
  File "C:\Users\Wen-Liang\AppData\Local\Programs\Python\Python311\Lib\site-packages\wandb\util.py", line 968, in check_retry_fn
    return fallback_retry_fn(e)
           ^^^^^^^^^^^^^^^^^^^^
  File "C:\Users\Wen-Liang\AppData\Local\Programs\Python\Python311\Lib\site-packages\wandb\util.py", line 910, in no_retry_auth
    raise CommError(
wandb.errors.CommError: It appears that you do not have permission to access the requested resource. Please reach out to the project owner to grant you access. If you have the correct permissions, verify that there are no issues with your networking setup.(Error 404: Not Found)
2024-06-30 10:03:29,042 DEBUG   HandlerThread:15384 [handler.py:handle_request():158] handle_request: shutdown
2024-06-30 10:03:29,042 INFO    HandlerThread:15384 [handler.py:finish():882] shutting down handler
2024-06-30 10:03:29,124 INFO    WriterThread:15384 [datastore.py:close():296] close: E:\huggingface_ex\wandb\run-20240630_100328-ylejexp4\run-ylejexp4.wandb
2024-06-30 10:03:29,732 INFO    SenderThread:15384 [sender.py:finish():1608] shutting down sender
